I'm sorry, but an uncaught exception occurred.

While running game code:
  File "game/script.rpy", line 19, in script
    man "Hello, I'm \"Man\" a simple Computer Science Student!"
Exception: Sayer 'man' is not defined.

-- Full Traceback ------------------------------------------------------------

Full traceback:
  File "game/script.rpy", line 19, in script
    man "Hello, I'm \"Man\" a simple Computer Science Student!"
  File "C:\Users\ednai\Documents\renpy-8.2.3-sdk\renpy\ast.py", line 2560, in execute
    Say.execute(self)
  File "C:\Users\ednai\Documents\renpy-8.2.3-sdk\renpy\ast.py", line 575, in execute
    who = eval_who(self.who, self.who_fast)
  File "C:\Users\ednai\Documents\renpy-8.2.3-sdk\renpy\ast.py", line 464, in eval_who
    raise Exception("Sayer '%s' is not defined." % who)
Exception: Sayer 'man' is not defined.

Windows-10-10.0.22631 AMD64
Ren'Py 8.2.3.24061702
Meet Reflections 1.0
Thu Aug 15 22:57:26 2024
